Workbook

Sheet Monitoring RKA 2026
A1: Bulan | B1: Wilayah | C1: PosAnggaran | D1: ProgramConsumed | E1: RealisasiConsumed | F1: ProgramActual | G1: RealisasiActual
A2: Jan | B2: Kantor Pusat | C2: Perawatan BMN | D2: 100000000 | E2: ='Hitung Per Bulan'!I2 -> 84845467162 | F2: 50000000 | G2: ='Hitung Per Bulan'!J2 -> 0
A3: Feb | B3: Kantor Pusat | C3: Perawatan BMN | D3: 23567624816 | E3: ='Hitung Per Bulan'!I3 -> 59570632314 | F3: 50000000 | G3: ='Hitung Per Bulan'!J3 -> 0
A4: Mar | B4: Kantor Pusat | C4: Perawatan BMN | D4: 227166881580 | E4: ='Hitung Per Bulan'!I4 -> 144879653762 | F4: 34189485820 | G4: ='Hitung Per Bulan'!J4 -> 48109844280
A5: Apr | B5: Kantor Pusat | C5: Perawatan BMN | D5: 59269584722 | E5: ='Hitung Per Bulan'!I5 | F5: 150000000 | G5: ='Hitung Per Bulan'!J5
A6: Mei | B6: Kantor Pusat | C6: Perawatan BMN | D6: 2449082158 | E6: ='Hitung Per Bulan'!I6 | F6: 270862500 | G6: ='Hitung Per Bulan'!J6
A7: Jun | B7: Kantor Pusat | C7: Perawatan BMN | D7: 4232140778 | E7: ='Hitung Per Bulan'!I7 | F7: 1144232361 | G7: ='Hitung Per Bulan'!J7
A8: Jul | B8: Kantor Pusat | C8: Perawatan BMN | D8: 150000000 | E8: ='Hitung Per Bulan'!I8 | F8: 12808685000 | G8: ='Hitung Per Bulan'!J8
A9: Agt | B9: Kantor Pusat | C9: Perawatan BMN | D9: 150000000 | E9: ='Hitung Per Bulan'!I9 | F9: 30371398896 | G9: ='Hitung Per Bulan'!J9
A10: Sep | B10: Kantor Pusat | C10: Perawatan BMN | D10: 150000000 | E10: ='Hitung Per Bulan'!I10 | F10: 32919933000 | G10: ='Hitung Per Bulan'!J10
A11: Okt | B11: Kantor Pusat | C11: Perawatan BMN | D11: 150000000 | E11: ='Hitung Per Bulan'!I11 | F11: 61587805112 | G11: ='Hitung Per Bulan'!J11
A12: Nov | B12: Kantor Pusat | C12: Perawatan BMN | D12: 122077000 | E12: ='Hitung Per Bulan'!I12 | F12: 35148562865 | G12: ='Hitung Per Bulan'!J12
A13: Des | B13: Kantor Pusat | C13: Perawatan BMN | D13: 55000000 | E13: ='Hitung Per Bulan'!I13 | F13: 108871425778 | G13: ='Hitung Per Bulan'!J13
... A64: Mar | B64: Kantor Pusat | C64: BUTAP KAI | D64: 443000000 | E64: ='Hitung Per Bulan'!I64 -> 61678750 | F64: 243000000 | G64: ='Hitung Per Bulan'!J64 -> 62518750
A65: Apr | B65: Kantor Pusat | C65: BUTAP KAI | D65: =1993000000+500000000 -> 2493000000 | E65: ='Hitung Per Bulan'!I65 | F65: 1243000000 | G65: ='Hitung Per Bulan'!J65
A66: Mei | B66: Kantor Pusat | C66: BUTAP KAI | D66: 593000000 | E66: ='Hitung Per Bulan'!I66 | F66: =593000000+1500000000 -> 2093000000 | G66: ='Hitung Per Bulan'!J66
A67: Jun | B67: Kantor Pusat | C67: BUTAP KAI | D67: =513000000+1000000000 -> 1513000000 | E67: ='Hitung Per Bulan'!I67 | F67: 1043000000 | G67: ='Hitung Per Bulan'!J67
A68: Jul | B68: Kantor Pusat | C68: BUTAP KAI | D68: 943000000 | E68: ='Hitung Per Bulan'!I68 | F68: 963000000 | G68: ='Hitung Per Bulan'!J68
A69: Agt | B69: Kantor Pusat | C69: BUTAP KAI | D69: 543000000 | E69: ='Hitung Per Bulan'!I69 | F69: 443000000 | G69: ='Hitung Per Bulan'!J69
A70: Sep | B70: Kantor Pusat | C70: BUTAP KAI | D70: 293000000 | E70: ='Hitung Per Bulan'!I70 | F70: 493000000 | G70: ='Hitung Per Bulan'!J70
A71: Okt | B71: Kantor Pusat | C71: BUTAP KAI | D71: 413000000 | E71: ='Hitung Per Bulan'!I71 | F71: 663000000 | G71: ='Hitung Per Bulan'!J71
A72: Nov | B72: Kantor Pusat | C72: BUTAP KAI | D72: 193000000 | E72: ='Hitung Per Bulan'!I72 | F72: 293000000 | G72: ='Hitung Per Bulan'!J72
A73: Des | B73: Kantor Pusat | C73: BUTAP KAI | D73: 113000000 | E73: ='Hitung Per Bulan'!I73 | F73: 113000000 | G73: ='Hitung Per Bulan'!J73
A74: Jan | B74: Kantor Pusat | C74: LAT IO | D74: 310000000 | E74: ='Hitung Per Bulan'!I74 -> 275097724 | F74: 310000000 | G74: ='Hitung Per Bulan'!J74 -> 275097724
A75: Feb | B75: Kantor Pusat | C75: LAT IO | D75: 310000000 | E75: ='Hitung Per Bulan'!I75 -> 626594334 | F75: 310000000 | G75: ='Hitung Per Bulan'!J75 -> 626594334
A76: Mar | B76: Kantor Pusat | C76: LAT IO | D76: 310000000 | E76: ='Hitung Per Bulan'!I76 -> 66225547 | F76: 310000000 | G76: ='Hitung Per Bulan'!J76 -> 66225547
A77: Apr | B77: Kantor Pusat | C77: LAT IO | D77: 420000000 | E77: ='Hitung Per Bulan'!I77 | F77: 420000000 | G77: ='Hitung Per Bulan'!J77
A78: Mei | B78: Kantor Pusat | C78: LAT IO | D78: 420000000 | E78: ='Hitung Per Bulan'!I78 | F78: 420000000 | G78: ='Hitung Per Bulan'!J78
A79: Jun | B79: Kantor Pusat | C79: LAT IO | D79: 420000000 | E79: ='Hitung Per Bulan'!I79 | F79: 420000000 | G79: ='Hitung Per Bulan'!J79
... A301: Des | B301: 2 BD | C301: Peralatan Khusus KAI | D301: 0 | E301: ='Hitung Per Bulan'!I301 | F301: 0 | G301: ='Hitung Per Bulan'!J301
A302: Jan | B302: 2 BD | C302: BUTAP BMN | D302: 0 | E302: ='Hitung Per Bulan'!I302 -> 0 | G302: ='Hitung Per Bulan'!J302 -> 0
A303: Feb | B303: 2 BD | C303: BUTAP BMN | D303: 0 | E303: ='Hitung Per Bulan'!I303 -> 0 | G303: ='Hitung Per Bulan'!J303 -> 0
A304: Mar | B304: 2 BD | C304: BUTAP BMN | D304: 0 | E304: ='Hitung Per Bulan'!I304 -> 0 | G304: ='Hitung Per Bulan'!J304 -> 0
A305: Apr | B305: 2 BD | C305: BUTAP BMN | D305: 0 | E305: ='Hitung Per Bulan'!I305 | G305: ='Hitung Per Bulan'!J305
A306: Mei | B306: 2 BD | C306: BUTAP BMN | D306: 0 | E306: ='Hitung Per Bulan'!I306 | G306: ='Hitung Per Bulan'!J306
A307: Jun | B307: 2 BD | C307: BUTAP BMN | D307: 0 | E307: ='Hitung Per Bulan'!I307 | G307: ='Hitung Per Bulan'!J307
A308: Jul | B308: 2 BD | C308: BUTAP BMN | D308: 0 | E308: ='Hitung Per Bulan'!I308 | G308: ='Hitung Per Bulan'!J308
A309: Agt | B309: 2 BD | C309: BUTAP BMN | D309: 0 | E309: ='Hitung Per Bulan'!I309 | G309: ='Hitung Per Bulan'!J309
A310: Sep | B310: 2 BD | C310: BUTAP BMN | D310: 0 | E310: ='Hitung Per Bulan'!I310 | G310: ='Hitung Per Bulan'!J310
A311: Okt | B311: 2 BD | C311: BUTAP BMN | D311: 0 | E311: ='Hitung Per Bulan'!I311 | G311: ='Hitung Per Bulan'!J311
...

Sheet Hitung Per Bulan
A1: Bulan | B1: Wilayah | C1: PosAnggaran | D1: ProgramConsumed | E1: RealisasiConsumed | F1: ProgramActual | G1: RealisasiActual | I1: RealisasiConsumed | J1: RealisasiActual | L1: Kum Consumed | M1: Kum Actual
A2: Jan | B2: Kantor Pusat | C2: Perawatan BMN | D2: 100000000 | E2: 84845467162 | F2: 50000000 | G2: 0 | I2: =IF(L2="","",L2) -> 84845467162 | J2: =IF(M2="","",M2) -> 0 | L2: 84845467162 | M2: 0
A3: Feb | B3: Kantor Pusat | C3: Perawatan BMN | D3: 23567624816 | E3: 59570632314 | F3: 50000000 | G3: 0 | I3: =IF(L3="","",L3-L2) -> 59570632314 | J3: =IF(M3="","",M3-M2) -> 0 | L3: 144416099476 | M3: 0
A4: Mar | B4: Kantor Pusat | C4: Perawatan BMN | D4: 227166881580 | E4: 46052581309 | F4: 34189485820 | G4: 34085923118 | I4: =IF(L4="","",L4-L3) -> 144879653762 | J4: =IF(M4="","",M4-M3) -> 48109844280 | L4: =SUMIFS(Pivot_!C:C,Pivot_!A:A,'Hitung Per Bulan'!B4,Pivot_!B:B,'Hitung Per Bulan'!C4) -> 289295753238 | M4: =SUMIFS(Pivot_!D:D,Pivot_!A:A,'Hitung Per Bulan'!B4,Pivot_!B:B,'Hitung Per Bulan'!C4) -> 48109844280
A5: Apr | B5: Kantor Pusat | C5: Perawatan BMN | D5: 59269584722 | F5: 150000000 | I5: =IF(L5="","",L5-L4) | J5: =IF(M5="","",M5-M4)
A6: Mei | B6: Kantor Pusat | C6: Perawatan BMN | D6: 2449082158 | F6: 270862500 | I6: =IF(L6="","",L6-L5) | J6: =IF(M6="","",M6-M5)
A7: Jun | B7: Kantor Pusat | C7: Perawatan BMN | D7: 4232140778 | F7: 1144232361 | I7: =IF(L7="","",L7-L6) | J7: =IF(M7="","",M7-M6)
A8: Jul | B8: Kantor Pusat | C8: Perawatan BMN | D8: 150000000 | F8: 12808685000 | I8: =IF(L8="","",L8-L7) | J8: =IF(M8="","",M8-M7)
A9: Agt | B9: Kantor Pusat | C9: Perawatan BMN | D9: 150000000 | F9: 30371398896 | I9: =IF(L9="","",L9-L8) | J9: =IF(M9="","",M9-M8)
A10: Sep | B10: Kantor Pusat | C10: Perawatan BMN | D10: 150000000 | F10: 32919933000 | I10: =IF(L10="","",L10-L9) | J10: =IF(M10="","",M10-M9)
A11: Okt | B11: Kantor Pusat | C11: Perawatan BMN | D11: 150000000 | F11: 61587805112 | I11: =IF(L11="","",L11-L10) | J11: =IF(M11="","",M11-M10)
A12: Nov | B12: Kantor Pusat | C12: Perawatan BMN | D12: 122077000 | F12: 35148562865 | I12: =IF(L12="","",L12-L11) | J12: =IF(M12="","",M12-M11)
A13: Des | B13: Kantor Pusat | C13: Perawatan BMN | D13: 55000000 | F13: 108871425778 | I13: =IF(L13="","",L13-L12) | J13: =IF(M13="","",M13-M12)
A14: Jan | B14: Kantor Pusat | C14: Perawatan KAI | D14: 0 | E14: 0 | F14: 0 | G14: 0 | I14: =IF(L14="","",L14) -> 0 | J14: =IF(M14="","",M14) -> 0 | L14: 0 | M14: 0
A15: Feb | B15: Kantor Pusat | C15: Perawatan KAI | D15: 0 | E15: 0 | F15: 0 | G15: 0 | I15: =IF(L15="","",L15-L14) -> 0 | J15: =IF(M15="","",M15-M14) -> 0 | L15: 0 | M15: 0
A16: Mar | B16: Kantor Pusat | C16: Perawatan KAI | D16: 0 | E16: 0 | F16: 0 | G16: 0 | I16: =IF(L16="","",L16-L15) -> 0 | J16: =IF(M16="","",M16-M15) -> 0 | L16: =SUMIFS(Pivot_!C:C,Pivot_!A:A,'Hitung Per Bulan'!B16,Pivot_!B:B,'Hitung Per Bulan'!C16) -> 0 | M16: =SUMIFS(Pivot_!D:D,Pivot_!A:A,'Hitung Per Bulan'!B16,Pivot_!B:B,'Hitung Per Bulan'!C16) -> 0
A17: Apr | B17: Kantor Pusat | C17: Perawatan KAI | D17: 0 | F17: 0 | I17: =IF(L17="","",L17-L16) | J17: =IF(M17="","",M17-M16)
A18: Mei | B18: Kantor Pusat | C18: Perawatan KAI | D18: 0 | F18: 0 | I18: =IF(L18="","",L18-L17) | J18: =IF(M18="","",M18-M17)
A19: Jun | B19: Kantor Pusat | C19: Perawatan KAI | D19: 0 | F19: 0 | I19: =IF(L19="","",L19-L18) | J19: =IF(M19="","",M19-M18)
A20: Jul | B20: Kantor Pusat | C20: Perawatan KAI | D20: 0 | F20: 0 | I20: =IF(L20="","",L20-L19) | J20: =IF(M20="","",M20-M19)
A21: Agt | B21: Kantor Pusat | C21: Perawatan KAI | D21: 0 | F21: 0 | I21: =IF(L21="","",L21-L20) | J21: =IF(M21="","",M21-M20)
A22: Sep | B22: Kantor Pusat | C22: Perawatan KAI | D22: 0 | F22: 0 | I22: =IF(L22="","",L22-L21) | J22: =IF(M22="","",M22-M21)
A23: Okt | B23: Kantor Pusat | C23: Perawatan KAI | D23: 0 | F23: 0 | I23: =IF(L23="","",L23-L22) | J23: =IF(M23="","",M23-M22)
A24: Nov | B24: Kantor Pusat | C24: Perawatan KAI | D24: 0 | F24: 0 | I24: =IF(L24="","",L24-L23) | J24: =IF(M24="","",M24-M23)
A25: Des | B25: Kantor Pusat | C25: Perawatan KAI | D25: 0 | F25: 0 | I25: =IF(L25="","",L25-L24) | J25: =IF(M25="","",M25-M24)
A26: Jan | B26: Kantor Pusat | C26: BBM Mekanik | D26: 0 | E26: 0 | F26: 0 | G26: 0 | I26: =IF(L26="","",L26) -> 0 | J26: =IF(M26="","",M26) -> 0 | L26: 0 | M26: 0
A27: Feb | B27: Kantor Pusat | C27: BBM Mekanik | D27: 0 | E27: 0 | F27: 0 | G27: 0 | I27: =IF(L27="","",L27-L26) -> 0 | J27: =IF(M27="","",M27-M26) -> 0 | L27: 0 | M27: 0
A28: Mar | B28: Kantor Pusat | C28: BBM Mekanik | D28: 0 | E28: 0 | F28: 0 | G28: 0 | I28: =IF(L28="","",L28-L27) -> 0 | J28: =IF(M28="","",M28-M27) -> 0 | L28: =SUMIFS(Pivot_!C:C,Pivot_!A:A,'Hitung Per Bulan'!B28,Pivot_!B:B,'Hitung Per Bulan'!C28) -> 0 | M28: =SUMIFS(Pivot_!D:D,Pivot_!A:A,'Hitung Per Bulan'!B28,Pivot_!B:B,'Hitung Per Bulan'!C28) -> 0
A29: Apr | B29: Kantor Pusat | C29: BBM Mekanik | D29: 0 | F29: 0 | I29: =IF(L29="","",L29-L28) | J29: =IF(M29="","",M29-M28)
A30: Mei | B30: Kantor Pusat | C30: BBM Mekanik | D30: 0 | F30: 0 | I30: =IF(L30="","",L30-L29) | J30: =IF(M30="","",M30-M29)
A31: Jun | B31: Kantor Pusat | C31: BBM Mekanik | D31: 0 | F31: 0 | I31: =IF(L31="","",L31-L30) | J31: =IF(M31="","",M31-M30)
A32: Jul | B32: Kantor Pusat | C32: BBM Mekanik | D32: 0 | F32: 0 | I32: =IF(L32="","",L32-L31) | J32: =IF(M32="","",M32-M31)
A33: Agt | B33: Kantor Pusat | C33: BBM Mekanik | D33: 0 | F33: 0 | I33: =IF(L33="","",L33-L32) | J33: =IF(M33="","",M33-M32)
A34: Sep | B34: Kantor Pusat | C34: BBM Mekanik | D34: 0 | F34: 0 | I34: =IF(L34="","",L34-L33) | J34: =IF(M34="","",M34-M33)
A35: Okt | B35: Kantor Pusat | C35: BBM Mekanik | D35: 0 | F35: 0 | I35: =IF(L35="","",L35-L34) | J35: =IF(M35="","",M35-M34)
A36: Nov | B36: Kantor Pusat | C36: BBM Mekanik | D36: 0 | F36: 0 | I36: =IF(L36="","",L36-L35) | J36: =IF(M36="","",M36-M35)
A37: Des | B37: Kantor Pusat | C37: BBM Mekanik | D37: 0 | F37: 0 | I37: =IF(L37="","",L37-L36) | J37: =IF(M37="","",M37-M36)
A38: Jan | B38: Kantor Pusat | C38: Peralatan Khusus KAI | D38: 0 | E38: 0 | F38: 0 | G38: 0 | I38: =IF(L38="","",L38) -> 0 | J38: =IF(M38="","",M38) -> 0 | L38: 0 | M38: 0
A39: Feb | B39: Kantor Pusat | C39: Peralatan Khusus KAI | D39: 0 | E39: 0 | F39: 0 | G39: 0 | I39: =IF(L39="","",L39-L38) -> 0 | J39: =IF(M39="","",M39-M38) -> 0 | L39: 0 | M39: 0
A40: Mar | B40: Kantor Pusat | C40: Peralatan Khusus KAI | D40: 0 | E40: 0 | F40: 0 | G40: 0 | I40: =IF(L40="","",L40-L39) -> 42457000 | J40: =IF(M40="","",M40-M39) -> 0 | L40: =SUMIFS(Pivot_!C:C,Pivot_!A:A,'Hitung Per Bulan'!B40,Pivot_!B:B,'Hitung Per Bulan'!C40) -> 42457000 | M40: =SUMIFS(Pivot_!D:D,Pivot_!A:A,'Hitung Per Bulan'!B40,Pivot_!B:B,'Hitung Per Bulan'!C40) -> 0
...

Sheet Pivot
B2: Row Labels | C2: Consumed | D2: Actual | E2: Sum of Selisih | G2: RKAO Disetujui | I2: Selisih (RKAO - Actual)
B3: 1 JAK | C3: 63265781000 | D3: 63265781000 | E3: 0 | G3: =SUM(G4:G10) -> 63265782000 | I3: =G3-D3 -> 1000
B4: BBM Mekanik | C4: 180000000 | D4: 180000000 | E4: 0 | G4: 180000000 | I4: =G4-D4 -> 0
B5: BUTAP BMN | C5: 0 | D5: 0 | E5: 0 | G5: 0 | I5: =G5-D5 -> 0
B6: BUTAP KAI | C6: 2561006000 | D6: 2561006000 | E6: 0 | G6: 2561006000 | I6: =G6-D6 -> 0
B7: LAT IO | C7: 3500000000 | D7: 3500000000 | E7: 0 | G7: 3500000000 | I7: =G7-D7 -> 0
B8: Peralatan Khusus KAI | C8: 400000000 | D8: 400000000 | E8: 0 | G8: 400000000 | I8: =G8-D8 -> 0
B9: Perawatan BMN | C9: 50254775000 | D9: 50254775000 | E9: 0 | G9: 50254776000 | I9: =G9-D9 -> 1000
B10: Perawatan KAI | C10: 6370000000 | D10: 6370000000 | E10: 0 | G10: 6370000000 | I10: =G10-D10 -> 0
B11: 1 JAK (LAA) | C11: 47253818337 | D11: 47253818000 | E11: -337 | G11: =SUM(G12:G18) -> 47253817201 | I11: =G11-D11 -> -799
B12: BBM Mekanik | C12: 0 | D12: 0 | E12: 0 | G12: 0 | I12: =G12-D12 -> 0
B13: BUTAP BMN | C13: 0 | D13: 0 | E13: 0 | G13: 0 | I13: =G13-D13 -> 0
B14: BUTAP KAI | C14: 1931870000 | D14: 1931870000 | E14: 0 | G14: 1931870000 | I14: =G14-D14 -> 0
B15: LAT IO | C15: 0 | D15: 0 | E15: 0 | G15: 0 | I15: =G15-D15 -> 0
B16: Peralatan Khusus KAI | C16: 200000000 | D16: 200000000 | E16: 0 | G16: 200000000 | I16: =G16-D16 -> 0
B17: Perawatan BMN | C17: 41949880337 | D17: 41949880000 | E17: -337 | G17: 41949878537 | I17: =G17-D17 -> -1463
B18: Perawatan KAI | C18: 3172068000 | D18: 3172068000 | E18: 0 | G18: 3172068664 | I18: =G18-D18 -> 664
B19: 2 BD | C19: 28292912000 | D19: 28292912000 | E19: 0 | G19: =SUM(G20:G26) -> 28292912000 | I19: =G19-D19 -> 0
B20: BBM Mekanik | C20: 118875000 | D20: 118875000 | E20: 0 | G20: 118875000 | I20: =G20-D20 -> 0
B21: BUTAP BMN | C21: 0 | E21: 0 | G21: 0 | I21: =G21-D21 -> 0
B22: BUTAP KAI | C22: 1162320000 | D22: 1162320000 | E22: 0 | G22: 1162320000 | I22: =G22-D22 -> 0
B23: LAT IO | C23: 2260000000 | D23: 2260000000 | E23: 0 | G23: 2260000000 | I23: =G23-D23 -> 0
B24: Peralatan Khusus KAI | C24: 705000000 | D24: 705000000 | E24: 0 | G24: 705000000 | I24: =G24-D24 -> 0
B25: Perawatan BMN | C25: 22542717000 | D25: 22542717000 | E25: 0 | G25: 22542717000 | I25: =G25-D25 -> 0
B26: Perawatan KAI | C26: 1504000000 | D26: 1504000000 | E26: 0 | G26: 1504000000 | I26: =G26-D26 -> 0
B27: 3 CN | C27: 26776307000 | D27: 26776307000 | E27: 0 | G27: =SUM(G28:G34) -> 26776308000 | I27: =G27-D27 -> 1000
B28: BBM Mekanik | C28: 90090000 | D28: 90090000 | E28: 0 | G28: 90090000 | I28: =G28-D28 -> 0
B29: BUTAP BMN | C29: 0 | D29: 0 | E29: 0 | G29: 0 | I29: =G29-D29 -> 0
B30: BUTAP KAI | C30: 1682602000 | D30: 1682602000 | E30: 0 | G30: 1682602000 | I30: =G30-D30 -> 0
B31: LAT IO | C31: 2501300000 | D31: 2501300000 | E31: 0 | G31: 2501300000 | I31: =G31-D31 -> 0
B32: Peralatan Khusus KAI | C32: 250000000 | D32: 250000000 | E32: 0 | G32: 250000000 | I32: =G32-D32 -> 0
B33: Perawatan BMN | C33: 20805475000 | D33: 20805475000 | E33: 0 | G33: 20805476000 | I33: =G33-D33 -> 1000
B34: Perawatan KAI | C34: 1446840000 | D34: 1446840000 | E34: 0 | G34: 1446840000 | I34: =G34-D34 -> 0
B35: 4 SM | C35: 22738648941 | D35: 22738649867 | E35: 926 | G35: =SUM(G36:G42) -> 22738650000 | I35: =G35-D35 -> 133
B36: BBM Mekanik | C36: 320100000 | D36: 320100000 | E36: 0 | G36: 320100000 | I36: =G36-D36 -> 0
B37: BUTAP BMN | C37: 0 | D37: 0 | E37: 0 | G37: 0 | I37: =G37-D37 -> 0
B38: BUTAP KAI | C38: 1684046000 | D38: 1684046000 | E38: 0 | G38: 1684046000 | I38: =G38-D38 -> 0
B39: LAT IO | C39: 2570000000 | D39: 2570000000 | E39: 0 | G39: 2570000000 | I39: =G39-D39 -> 0
B40: Peralatan Khusus KAI | C40: 150000000 | D40: 150000000 | E40: 0 | G40: 150000000 | I40: =G40-D40 -> 0
B41: Perawatan BMN | C41: 17365502941 | D41: 17365503867 | E41: 926 | G41: 17365504000 | I41: =G41-D41 -> 133
...

Sheet ZFM01
A1: Funds Center/Commitment Item | B1: RKAP | C1: Release | D1: Comitment | E1: Actual | F1: Consumed | G1: Available | H1: NotRelease | I1: Daerah | J1: Jenis
A2: 1182000000 Persediaan Prasarana Perkeretaapian dan Umum | B2: 92766189536 | C2: 92766189536 | D2: 85954753160 | E2: 46437298 | F2: 86001190458 | G2: 6764999078 | H2: 0 | I2: KP | J2: Perawatan BMN
A3: 4211000000 Perawatan Bangunan Lainnya KAI | B3: 0 | C3: 0 | D3: 0 | E3: 0 | F3: 0 | G3: 0 | H3: 0 | I3: KP | J3: BUTAP KAI
A4: 4221421010 Peralatan Dalam Sinyal Elektrik BMN | B4: 57855713800 | C4: 57855713800 | D4: 52055713800 | E4: 5400000000 | F4: 57455713800 | G4: 400000000 | H4: 0 | I4: KP | J4: Perawatan BMN
A5: 4221422010 Peralatan Luar Sinyal Elektrik BMN | B5: 32816341758 | C5: 32816341758 | D5: 2662482200 | E5: 28199383820 | F5: 30861866020 | G5: 1954475738 | H5: 0 | I5: KP | J5: Perawatan BMN
A6: 4221423010 Peralatan Dalam Sinyal Mekanik BMN | B6: 2001312000 | C6: 2001312000 | D6: 2001312000 | E6: 0 | F6: 2001312000 | G6: 0 | H6: 0 | I6: KP | J6: Perawatan BMN
A7: 4221425010 Pengamanan Perlintasan Sebidang BMN | B7: 17448622000 | C7: 17448622000 | D7: 17448621050 | E7: 0 | F7: 17448621050 | G7: 950 | H7: 0 | I7: KP | J7: Perawatan BMN
A8: 4221426010 Pesawat Telepon BMN | B8: 3947046000 | C8: 3947046000 | D8: 3129065362 | E8: 0 | F8: 3129065362 | G8: 817980638 | H8: 0 | I8: KP | J8: Perawatan BMN
A9: 4221427010 Transmisi Komunikasi BMN | B9: 63547356665 | C9: 63547356665 | D9: 54626167394 | E9: 8154071362 | F9: 62780238756 | G9: 767117909 | H9: 0 | I9: KP | J9: Perawatan BMN
A10: 4221428010 Peralatan Pendukung Sintel BMN | B10: 1577077000 | C10: 1577077000 | D10: 67563765 | E10: 0 | F10: 67563765 | G10: 1509513235 | H10: 0 | I10: KP | J10: Perawatan BMN
A11: 4221429011 Beban Pemakaian Alat Kerja pendukung perawatan BMN | B11: 1010789797 | C11: 1010789797 | D11: 0 | E11: 0 | F11: 0 | G11: 1010789797 | H11: 0 | I11: KP | J11: Perawatan BMN
A12: 4221521010 Catu Daya LAA BMN | B12: 26083685696 | C12: 26083685696 | D12: 13509377389 | E12: 6309951800 | F12: 19819329189 | G12: 6264356507 | H12: 0 | I12: KP | J12: Perawatan BMN
A13: 4221522010 Tranmisi Tenaga LAA BMN | B13: 11951319669 | C13: 11951319669 | D13: 9730852838 | E13: 0 | F13: 9730852838 | G13: 2220466831 | H13: 0 | I13: KP | J13: Perawatan BMN
... A37: 5400000000 Penyusutan AT Lainnya (Fasilitas Umum) | B37: 0 | C37: 0 | D37: 0 | E37: 410815330 | F37: 410815330 | G37: -410815330 | H37: 0 | I37: KP | J37: -
A38: 10025000 Signalling, Telecomm & Electricity | B38: 362606000000 | C38: 360188000000 | D38: 241340000000 | E38: 56192569755 | F38: 297533000000 | G38: 62655275823 | H38: 2417500000 | I38: KP | J38: #N/A
A39: 1182000000 Persediaan Prasarana Perkeretaapian dan Umum | B39: 25194775704 | C39: 25194775704 | D39: 17081409964 | E39: 0 | F39: 17081409964 | G39: 8113365740 | H39: 0 | I39: 1 Jak STL | J39: Perawatan BMN
A40: 4123210010 Gaji &Tunjangan Pegawai Perawatan Sarana | B40: 17002987 | C40: 17002987 | D40: 0 | E40: 0 | F40: 0 | G40: 17002987 | H40: 0 | I40: 1 Jak STL | J40: -
A41: 4123240000 Lembur dan Perangsang Pegawai Perawatan Sarana | B41: 32320895 | C41: 32320895 | D41: 0 | E41: 0 | F41: 0 | G41: 32320895 | H41: 0 | I41: 1 Jak STL | J41: -
A42: 4123250000 Pakaian Dinas Pegawai Perawatan Sarana | B42: 550084 | C42: 550084 | D42: 0 | E42: 0 | F42: 0 | G42: 550084 | H42: 0 | I42: 1 Jak STL | J42: -
A43: 4221421010 Peralatan Dalam Sinyal Elektrik BMN | B43: 400000000 | C43: 400000000 | D43: 0 | E43: 0 | F43: 0 | G43: 400000000 | H43: 0 | I43: 1 Jak STL | J43: Perawatan BMN
A44: 4221422010 Peralatan Luar Sinyal Elektrik BMN | B44: 2000000000 | C44: 2000000000 | D44: 0 | E44: 0 | F44: 0 | G44: 2000000000 | H44: 0 | I44: 1 Jak STL | J44: Perawatan BMN
A45: 4221423010 Peralatan Dalam Sinyal Mekanik BMN | B45: 100000000 | C45: 100000000 | D45: 0 | E45: 0 | F45: 0 | G45: 100000000 | H45: 0 | I45: 1 Jak STL | J45: Perawatan BMN
A46: 4221424010 Peralatan Luar Sinyal Mekanik BMN | B46: 400000000 | C46: 400000000 | D46: 0 | E46: 0 | F46: 0 | G46: 400000000 | H46: 0 | I46: 1 Jak STL | J46: Perawatan BMN
A47: 4221425010 Pengamanan Perlintasan Sebidang BMN | B47: 1300000000 | C47: 1300000000 | D47: 463560600 | E47: 0 | F47: 463560600 | G47: 836439400 | H47: 0 | I47: 1 Jak STL | J47: Perawatan BMN
A48: 4221427010 Transmisi Komunikasi BMN | B48: 6000000000 | C48: 6000000000 | D48: 2487092234 | E48: 0 | F48: 2487092234 | G48: 3512907766 | H48: 0 | I48: 1 Jak STL | J48: Perawatan BMN
A49: 4221428010 Peralatan Pendukung Sintel BMN | B49: 4260000000 | C49: 4260000000 | D49: 480263597 | E49: 496793192 | F49: 977056789 | G49: 3282943211 | H49: 0 | I49: 1 Jak STL | J49: Perawatan BMN
A50: 4221428011 Bangunan Sintel BMN | B50: 1000000000 | C50: 1000000000 | D50: 0 | E50: 0 | F50: 0 | G50: 1000000000 | H50: 0 | I50: 1 Jak STL | J50: Perawatan BMN
... A77: 5140000000 Lembur dan Perangsang Pegawai Umum & Administrasi | B77: 0 | C77: 0 | D77: 0 | E77: 416016 | F77: 416016 | G77: -416016 | H77: 0 | I77: 1 Jak STL | J77: -
A78: 21022000 Sintelis | B78: 111569000000 | C78: 110898000000 | D78: 21437086131 | E78: 12533163050 | F78: 33970249181 | G78: 76927561010 | H78: 671501500 | I78: 1 Jak STL | J78: #N/A
A79: 1182000000 Persediaan Prasarana Perkeretaapian dan Umum | B79: 4044107500 | C79: 4044107500 | D79: 1518071200 | E79: 585361000 | F79: 2103432200 | G79: 1940675300 | H79: 0 | I79: 1 Jak LAA | J79: Perawatan BMN
A80: 4123110010 Gaji &Tunjangan Pegawai Operasi Sarana | B80: 0 | C80: 0 | D80: 0 | E80: -2900000 | F80: -2900000 | G80: 2900000 | H80: 0 | I80: 1 Jak LAA | J80: -
A81: 4221521010 Catu Daya LAA BMN | B81: 1657269514 | C81: 1657269514 | D81: 0 | E81: 125198600 | F81: 125198600 | G81: 1532070914 | H81: 0 | I81: 1 Jak LAA | J81: Perawatan BMN
A82: 4221522010 Tranmisi Tenaga LAA BMN | B82: 30639775739 | C82: 30639775739 | D82: 16588171728 | E82: 7766359971 | F82: 24354531699 | G82: 6285244040 | H82: 0 | I82: 1 Jak LAA | J82: Perawatan BMN
A83: 4221523010 Pengendalian Catu Daya LAA BMN | B83: 288221000 | C83: 288221000 | D83: 0 | E83: 0 | F83: 0 | G83: 288221000 | H83: 0 | I83: 1 Jak LAA | J83: Perawatan BMN
A84: 4221524010 Tanda Semboyan LAA BMN | B84: 593000000 | C84: 593000000 | D84: 0 | E84: 0 | F84: 0 | G84: 593000000 | H84: 0 | I84: 1 Jak LAA | J84: Perawatan BMN
A85: 4221525010 Bangunan LAA BMN | B85: 1210765056 | C85: 1210765056 | D85: 0 | E85: 104534440 | F85: 104534440 | G85: 1106230616 | H85: 0 | I85: 1 Jak LAA | J85: Perawatan BMN
A86: 4221526010 Sistim Proteksi LAA BMN | B86: 720219728 | C86: 720219728 | D86: 0 | E86: 396500562 | F86: 396500562 | G86: 323719166 | H86: 0 | I86: 1 Jak LAA | J86: Perawatan BMN
A87: 4221527010 Pendukung LAA BMN | B87: 2796520000 | C87: 2796520000 | D87: 564674777 | E87: 654736071 | F87: 1219410848 | G87: 1577109152 | H87: 0 | I87: 1 Jak LAA | J87: Perawatan BMN
A88: 4222521010 Catu Daya LAA KAI | B88: 231587382 | C88: 231587382 | D88: 0 | E88: 0 | F88: 0 | G88: 231587382 | H88: 0 | I88: 1 Jak LAA | J88: Perawatan KAI
A89: 4222522010 Tranmisi Tenaga LAA KAI | B89: 180831882 | C89: 180831882 | D89: 0 | E89: 0 | F89: 0 | G89: 180831882 | H89: 0 | I89: 1 Jak LAA | J89: Perawatan KAI
...

Sheet Pivot_
B1: Row Labels | C1: Sum of Consumed | D1: Sum of Actual
B2: 1 Jak LAA | C2: 29208950672 | D2: 9920320967
A3: 1 Jak (LAA) | B3: BUTAP KAI | C3: 235978350 | D3: 158206850
A4: =A3 -> 1 Jak (LAA) | B4: Peralatan Khusus KAI | C4: 66464000 | D4: 24488000
A5: =A4 -> 1 Jak (LAA) | B5: Perawatan BMN | C5: 28303608349 | D5: 9632690644
A6: =A5 -> 1 Jak (LAA) | B6: Perawatan KAI | C6: 602899973 | D6: 104935473
B7: 1 Jak STL | C7: 23093290005 | D7: 1656203874
A8: 1 Jak | B8: BBM Mekanik | C8: 28710000 | D8: 0
A9: =A8 -> 1 Jak | B9: BUTAP KAI | C9: 592051011 | D9: 207870775
A10: =A9 -> 1 Jak | B10: LAT IO | C10: 675269947 | D10: 675269947
A11: =A10 -> 1 Jak | B11: Peralatan Khusus KAI | C11: 0 | D11: 0
A12: =A11 -> 1 Jak | B12: Perawatan BMN | C12: 21266339047 | D12: 704063152
A13: =A12 -> 1 Jak | B13: Perawatan KAI | C13: 530920000 | D13: 69000000
B14: 2 Bd | C14: 18119039072 | D14: 1364602331
A15: =B14 -> 2 Bd | B15: BBM Mekanik | C15: 15775000 | D15: 7520000
A16: =A15 -> 2 Bd | B16: BUTAP KAI | C16: 225859389 | D16: 183468889
A17: =A16 -> 2 Bd | B17: LAT IO | C17: 474175238 | D17: 474175238
A18: =A17 -> 2 Bd | B18: Peralatan Khusus KAI | C18: 497734500 | D18: 0
A19: =A18 -> 2 Bd | B19: Perawatan BMN | C19: 16273511161 | D19: 699438204
A20: =A19 -> 2 Bd | B20: Perawatan KAI | C20: 631983784 | D20: 0
B21: 3 Cn | C21: 12199128376 | D21: 838605453
A22: =B21 -> 3 Cn | B22: BBM Mekanik | C22: 11205000 | D22: 0
A23: =A22 -> 3 Cn | B23: BUTAP KAI | C23: 345568297 | D23: 204075285
A24: =A23 -> 3 Cn | B24: LAT IO | C24: 493648655 | D24: 493648655
A25: =A24 -> 3 Cn | B25: Peralatan Khusus KAI | C25: 0 | D25: 0
A26: =A25 -> 3 Cn | B26: Perawatan BMN | C26: 11301848786 | D26: 132106375
A27: =A26 -> 3 Cn | B27: Perawatan KAI | C27: 46857638 | D27: 8775138
B28: 4 Sm | C28: 10425260223 | D28: 1080690309
A29: =B28 -> 4 Sm | B29: BBM Mekanik | C29: 71775000 | D29: 71775000
A30: =A29 -> 4 Sm | B30: BUTAP KAI | C30: 278221421 | D30: 199894421
A31: =A30 -> 4 Sm | B31: LAT IO | C31: 569677542 | D31: 569677542
A32: =A31 -> 4 Sm | B32: Peralatan Khusus KAI | C32: 41856000 | D32: 41856000
A33: =A32 -> 4 Sm | B33: Perawatan BMN | C33: 9439022660 | D33: 197487346
A34: =A33 -> 4 Sm | B34: Perawatan KAI | C34: 24707600 | D34: 0
B35: 5 Pwt | C35: 15493088575 | D35: 1158561433
A36: =B35 -> 5 Pwt | B36: BBM Mekanik | C36: 32848750 | D36: 32848750
A37: =A36 -> 5 Pwt | B37: BUTAP KAI | C37: 940203567 | D37: 214869830
A38: =A37 -> 5 Pwt | B38: LAT IO | C38: 573387303 | D38: 573387303
A39: =A38 -> 5 Pwt | B39: Peralatan Khusus KAI | C39: 0 | D39: 0
A40: =A39 -> 5 Pwt | B40: Perawatan BMN | C40: 13450818955 | D40: 337455550
...

Sheet Rekap
B3: TOTAL STE
B4: Daerah | C4: RKAO Disetujui | D4: RKAP SAP | E4: Release SAP | F4: % Release | G4: Consume SAP | H4: % Consume | I4: Actual SAP | J4: % Actual | K4: Available SAP
B5: 1 Jak LAA | C5: 47253817201 | D5: 47253817201 | E5: 46778119701 | F5: 0.9899 | G5: 29208950672 | H5: 0.6244 | I5: 9920320967 | J5: 0.2121 | K5: 17569169029
B6: 1 Jak STL | C6: 63265782000 | D6: 63265781854 | E6: 62594280354 | F6: 0.9894 | G6: 23093290005 | H6: 0.3689 | I6: 1656203874 | J6: 0.0265 | K6: 39500990349
B7: 2 Bd | C7: 28292912000 | D7: 28192912000 | E7: 27781832000 | F7: 0.9819 | G7: 18119039072 | H7: 0.6522 | I7: 1364602331 | J7: 0.0491 | K7: 9662792928
B8: 3 Cn | C8: 26776308000 | D8: 29024830540 | E8: 28575430040 | F8: 1.0672 | G8: 12199128376 | H8: 0.4269 | I8: 838605453 | J8: 0.0293 | K8: 16376301664
B9: 4 Sm | C9: 22738650000 | D9: 22738649560 | E9: 22323388060 | F9: 0.9817 | G9: 10425260223 | H9: 0.467 | I9: 1080690309 | J9: 0.0484 | K9: 11898127837
B10: 5 Pwt | C10: 27448857000 | D10: 27448857400 | E10: 26923645235 | F10: 0.9809 | G10: 15493088575 | H10: 0.5754 | I10: 1158561433 | J10: 0.043 | K10: 11430556660
B11: 6 Yk | C11: 35394555000 | D11: 35583038437 | E11: 35051993024 | F11: 0.9903 | G11: 13671567169 | H11: 0.39 | I11: 1219678277 | J11: 0.0348 | K11: 21380425855
B12: 7 Mn | C12: 13759223000 | D12: 13619223000 | E12: 13359083500 | F12: 0.9709 | G12: 7750632080 | H12: 0.5802 | I12: 804137941 | J12: 0.0602 | K12: 5608451420
B13: 8 Sb | C13: 33298000000 | D13: 33504140252 | E13: 32977805327 | F13: 0.9904 | G13: 21748614036 | H13: 0.6595 | I13: 2496931968 | J13: 0.0757 | K13: 11229191291
B14: 9 Jr | C14: 12904694000 | D14: 12854694000 | E14: 12622019000 | F14: 0.9781 | G14: 1591821260 | H14: 0.1261 | I14: 684092964 | J14: 0.0542 | K14: 11030197740
B15: I Su | C15: 14076601000 | D15: 14076601000 | E15: 13603793250 | F15: 0.9664 | G15: 1579104140 | H15: 0.1161 | I15: 646810092 | J15: 0.0475 | K15: 12024689110
B16: II Pd | C16: 2349760730 | D16: 2349760730 | E16: 2247760730 | F16: 0.9566 | G16: 524346780 | H16: 0.2333 | I16: 81050880 | J16: 0.0361 | K16: 1723413950
... B20: TOTAL | C20: 730326988931 | D20: 730383339169 | E20: 721321342416 | F20: 0.9876 | G20: 485086758336 | H20: 0.6725 | I20: 74235716271 | J20: 0.1029 | K20: 236234584080
B22: Perawatan BMN
B23: Daerah | C23: RKAO Disetujui | D23: RKAP SAP | E23: Release SAP | F23: % Release | G23: Consume SAP | H23: % Consume | I23: Actual SAP | J23: % Actual | K23: Available SAP
B24: 1 Jak LAA | C24: 41949878537 | D24: 41949878537 | E24: 41949878537 | F24: 1 | G24: 28303608349 | H24: 0.6747 | I24: 9632690644 | J24: 0.2296 | K24: 13646270188
B25: 1 Jak STL | C25: 50254776000 | D25: 50254775704 | E25: 50254775704 | F25: 1 | G25: 21266339047 | H25: 0.4232 | I25: 704063152 | J25: 0.014 | K25: 28988436657
B26: 2 Bd | C26: 22542717000 | D26: 22542717000 | E26: 22542717000 | F26: 1 | G26: 16273511161 | H26: 0.7219 | I26: 699438204 | J26: 0.031 | K26: 6269205839
B27: 3 Cn | C27: 20805476000 | D27: 23053998540 | E27: 23053998540 | F27: 1.1081 | G27: 11301848786 | H27: 0.4902 | I27: 132106375 | J27: 0.0057 | K27: 11752149754
B28: 4 Sm | C28: 17365504000 | D28: 17365503560 | E28: 17365503560 | F28: 1 | G28: 9439022660 | H28: 0.5436 | I28: 197487346 | J28: 0.0114 | K28: 7926480900
B29: 5 Pwt | C29: 20087368000 | D29: 20087368000 | E29: 20087368000 | F29: 1 | G29: 13450818955 | H29: 0.6696 | I29: 337455550 | J29: 0.0168 | K29: 6636549045
B30: 6 Yk | C30: 28538689000 | D30: 28538688812 | E30: 28538688812 | F30: 1 | G30: 12466034712 | H30: 0.4368 | I30: 454542040 | J30: 0.0159 | K30: 16072654100
B31: 7 Mn | C31: 9243055000 | D31: 9243055000 | E31: 9243055000 | F31: 1 | G31: 7153737482 | H31: 0.774 | I31: 253379843 | J31: 0.0274 | K31: 2089317518
B32: 8 Sb | C32: 26583433000 | D32: 26583433552 | E32: 26583433552 | F32: 1 | G32: 20894334901 | H32: 0.786 | I32: 1705110618 | J32: 0.0641 | K32: 5689098651
B33: 9 Jr | C33: 11122934000 | D33: 11122934000 | E33: 11122934000 | F33: 1 | G33: 1126417820 | H33: 0.1013 | I33: 421465514 | J33: 0.0379 | K33: 9996516180
B34: I Su | C34: 8737570000 | D34: 8737570000 | E34: 8737570000 | F34: 1 | G34: 860133360 | H34: 0.0984 | I34: 148749912 | J34: 0.017 | K34: 7877436640
B35: II Pd | C35: 1871950730 | D35: 1871950730 | E35: 1871950730 | F35: 1 | G35: 483831830 | H35: 0.2585 | I35: 65501830 | J35: 0.035 | K35: 1388118900
B36: III Pg | C36: 0 | D36: 0 | E36: 0 | G36: 0 | I36: 0 | K36: 0
B37: IV Tnk | C37: 30325250000 | D37: 30325250000 | E37: 30325250000 | F37: 1 | G37: 23157828727 | H37: 0.7636 | I37: 769817047 | J37: 0.0254 | K37: 7167421273
B38: KP | C38: 317562391000 | D38: 315313866921 | E38: 315313866921 | F38: 0.9929 | G38: 289295753238 | H38: 0.9175 | I38: 48109844280 | J38: 0.1526 | K38: 26018113683
B39: TOTAL | C39: 606990992267 | D39: 606990990356 | E39: 606990990356 | F39: 1 | G39: 455473221028 | H39: 0.7504 | I39: 63631652355 | J39: 0.1048 | K39: 151517769328
B41: Perawatan KAI
B42: Daerah | C42: RKAO Disetujui | D42: RKAP | E42: Release | F42: % Release | G42: Consume | H42: % Consume | I42: Actual | J42: % Actual | K42: Available
B43: 1 Jak LAA | C43: 3172068664 | D43: 3172068664 | E43: 3172068664 | F43: 1 | G43: 602899973 | H43: 0.1901 | I43: 104935473 | J43: 0.0331 | K43: 2569168691
B44: 1 Jak STL | C44: 6370000000 | D44: 6370000000 | E44: 6370000000 | F44: 1 | G44: 530920000 | H44: 0.0833 | I44: 69000000 | J44: 0.0108 | K44: 5839080000
B45: 2 Bd | C45: 1504000000 | D45: 1504000000 | E45: 1504000000 | F45: 1 | G45: 631983784 | H45: 0.4202 | I45: 0 | J45: 0 | K45: 872016216
B46: 3 Cn | C46: 1446840000 | D46: 1446840000 | E46: 1446840000 | F46: 1 | G46: 46857638 | H46: 0.0324 | I46: 8775138 | J46: 0.0061 | K46: 1399982362
B47: 4 Sm | C47: 649000000 | D47: 649000000 | E47: 649000000 | F47: 1 | G47: 24707600 | H47: 0.0381 | I47: 0 | J47: 0 | K47: 624292400
...
